Workbook

Sheet Dados Básicos
B2: Os dados BÁSICOS devem ser preenchidos pelo cliente/responsável e será a primeira inserção de dados/input que ele fará na plataforma; Nenhuma das informções dos dados básicos precisam estar no dashboard; A frequência das atualizações dos dados básicos será baixa, tipo anual. | H2: DADOS BÁSICOS/INICIAIS | I2: TIPO DE RESPOSTA
I3: DESCRIÇÃO | J3: SIM /NÃO
H4: Proprietário? | I4: X
H5: Município/Estado? | I5: X
H6: Próprio ou Arrendamento? | I6: X
H7: Qual o Índice Pluviométrico? | I7: X
H8: Qual a área total em há? | I8: X
H9: Qual a área útil de pastagem em há? | I9: X
H10: ÁREA
H11: Qual a quantidade Pastos? | I11: X
H12: Qual o tamanho médio dos pastos? | I12: X
H13: Faz rotacionado? | J13: X
H14: Em quantos % da área? | I14: X
H15: Faz Adubação? | J15: X
H16: Faz Correção de solo? | J16: X
H17: Com qual rotina? | I17: X
H18: Possue área destinada a produção de volumoso? | J18: X
H19: Qual o tamanho (ha)? | I19: X
H20: Faz integração Lavoura Pecuária? | J20: X
H21: PRODUÇÃO
H22: Qual a quantidade de Animais? | I22: X
H23: Qual o sexo dos Animais? | I23: X
H24: Qual o tipo/raça dos Animais? | I24: X
H25: Qual o tipo de Suplementação? | I25: X
H26: Faz cria, recria ou engorda? | I26: X
H27: Qual a quantidade de Animais por lote e Peso? | I27: X
H28: Compra de gado de produtor ou Leilão? | I28: X
H29: Qual o Tipo de Terminação à pasto/TIP/confinamento? | I29: X
H30: Qual a Taxa de Desfrute/Quantidade de Animais Vendidos/ano? | I30: X
H31: Qual a idade média de abate? | I31: X
H32: Quais as plantas frigoríficas mais utilizadas? | I32: X
H33: GESTÃO
H34: Qual a quantidade de funcionários? | I34: X
H35: Utiliza algum software de gestão, qual? | J35: X
H36: Qual software de gestão? | I36: X
H37: Possui Balança? | J37: X
H38: Qual frequência de pesagem? | I38: X
H39: Utiliza controle individual Brinco/chip? | J39: X
H40: Brinco/chip? | I40: X
H41: TERMINAÇÃO
...

Sheet Dados de Prod
G4: Os dados de PRODUÇÃO devem ser preenchidos pelo cliente
G5: Deve ser feito nas primeiras semanas (Projeção)
G6: Deve ser projetado até o desfrute/venda/abate do animal | H6: HISTÓRICO DO PLANTEL
G7: Deve conter os seguintes dados: | I7: Sexo | J7: Idade (m) | K7: Quant. | L7: Peso kg | M7: Peso @ | N7: Valor de Compra/Aquisição
G8: Deve ser separado por Lote/Pasto/Curral | H8: Lote 1 | I8: M | J8: 10 | K8: 200 | L8: 210 | M8: =L8/30 -> 7 | N8: =410*M8 -> 2870
G9: Se for pasto ele deve descrever, tipo: Pasto da Mata | H9: Lote 2 | I9: M | J9: 12 | K9: 500 | L9: 240 | M9: =L9/30 -> 8 | N9: =400*M9 -> 3200
G10: Se for lote ou curral vai ser numérico, Tipo: Lote 01; Curral 01 | H10: Lote 3 | I10: M | J10: 14 | K10: 300 | L10: 270 | M10: =L10/30 -> 9 | N10: =390*M10 -> 3510
G11: Não pode haver limite de lotes, o cliente pode ter 50 lotes...
G14: Deve ser inseridos os dados de ganho médio diário (GMD) em quilos para cada lote
G15: Segue exemplo: | H15: PROJEÇÃO DE GANHO (kg)
G16: Quem vai determinar o GMD será o cliente juntamente com seu responsável Técnico | I16: Mês 1 | J16: Mês 2 | K16: Mês 3 | L16: Mês 4 | M16: Mês 5 | N16: Mês 6 | O16: Mês 7 | P16: Mês 8
G17: Planilha estática, ainda não possui amarrações, somente dados | I17: Jan | J17: fev | K17: Mar | L17: Abr | M17: Mai | N17: Jun | O17: Jul | P17: Ago
H18: Lote 1 | I18: 0.9 | J18: 0.9 | K18: 0.9 | L18: 0.8 | M18: 0.7 | N18: 0.7 | O18: 0.7 | P18: 0.7
H19: Lote 2 | I19: 0.9 | J19: 0.9 | K19: 0.9 | L19: 0.8 | M19: 0.7 | N19: 0.7 | O19: 0.7 | P19: 0.7
H20: Lote 3 | I20: 0.9 | J20: 0.9 | K20: 0.9 | L20: 0.8 | M20: 0.7 | N20: 0.7 | O20: 0.7 | P20: 0.7
B23: Os dados de Produção devem ser preenchidos logo depois do preenchimento dos dados Básicos, deve s feito pelo cliente/responsável e com eles vamos dar vazão a todos os demais dados e amarrações; Deve sofrer alterações MENSAIS; | G23: Com esses dados listado podemos fazer automaticamente a Evolução de Peso Lote a Lote | T23: Lote 1
G24: Deve ser feito em Kg´s e em @´s | H24: EVOLUÇÃO DE PESO (kg) | T24: 0 | U24: =I28 -> 210
G25: Tanto o quadro 1 e 2 podem ser demosntrado no formato de Planilha como segue o | H25: 1 | I25: Mês 0 | J25: Mês 1 | K25: Mês 2 | L25: Mês 3 | M25: Mês 4 | N25: Mês 5 | O25: Mês 6 | P25: Mês 7 | Q25: Mês 8 | T25: Jan | U25: =J28 -> 237.9
G26: exemplo | I26: inicial | J26: Jan | K26: Fev | L26: Mar | M26: Abr | N26: Mai | O26: Jun | P26: Jul | Q26: Ago | T26: Fev | U26: =K28 -> 263.1
G27: Lembrando que até agora é uma projeção, então temos que pensar em um quadro | H27: Dias | J27: 31 | K27: 28 | L27: 31 | M27: 30 | N27: 31 | O27: 30 | P27: 31 | Q27: 31 | T27: Mar | U27: =L28 -> 291
G28: comparativo com Projetado e Realizado | H28: Lote 1 | I28: =L8 -> 210 | J28: =(I18*J27)+I28 -> 237.9 | K28: =(J18*K27)+J28 -> 263.1 | L28: =(K18*L27)+K28 -> 291 | M28: =(L18*M27)+L28 -> 315 | N28: =(M18*N27)+M28 -> 336.7 | O28: =(N18*O27)+N28 -> 357.7 | P28: =(O18*P27)+O28 -> 379.4 | Q28: =(P18*Q27)+P28 -> 401.1 | T28: Abr | U28: =M28 -> 315
G29: De período em perído ele deve pesar o gado e inserir o peso encontrado dos animais | H29: Lote 2 | I29: =L9 -> 240 | J29: =(I19*J27)+I29 -> 267.9 | K29: =(J19*K27)+J29 -> 293.1 | L29: =(K19*L27)+K29 -> 321 | M29: =(L19*M27)+L29 -> 345 | N29: =(M19*N27)+M29 -> 366.7 | O29: =(N19*O27)+N29 -> 387.7 | P29: =(O19*P27)+O29 -> 409.4 | Q29: =(P19*Q27)+P29 -> 431.1 | T29: Mai | U29: =N28 -> 336.7
G30: Como sugestão podemos pensar em um gráfico para o Dashboard com Evolução por lote | H30: Lote 3 | I30: =L10 -> 270 | J30: =(I20*J27)+I30 -> 297.9 | K30: =(J20*K27)+J30 -> 323.1 | L30: =(K20*L27)+K30 -> 351 | M30: =(L20*M27)+L30 -> 375 | N30: =(M20*N27)+M30 -> 396.7 | O30: =(N20*O27)+N30 -> 417.7 | P30: =(O20*P27)+O30 -> 439.4 | T30: Jun | U30: =O28 -> 357.7
T31: Jul | U31: =P28 -> 379.4
T32: Ago | U32: =Q28 -> 401.1
H33: EVOLUÇÃO DE PESO (@)
H34: 2 | I34: Mês 0 | J34: Mês 1 | K34: Mês 2 | L34: Mês 3 | M34: Mês 4 | N34: Mês 5 | O34: Mês 6 | P34: Mês 7 | Q34: Mês 8
I35: inicial | J35: Jan | K35: Fev | L35: Mar | M35: Abr | N35: Mai | O35: Jun | P35: Jul | Q35: Ago
H36: Lote 1 | I36: =I28/30 -> 7 | J36: =J28/30 -> 7.93 | K36: =K28/30 -> 8.77 | L36: =L28/30 -> 9.7 | M36: =M28/30 -> 10.5 | N36: =N28/30 -> 11.223333 | O36: =O28/30 -> 11.923333 | P36: =P28/30 -> 12.646667 | Q36: =Q28/30 -> 13.37
H37: Lote 2 | I37: =I29/30 -> 8 | J37: =J29/30 -> 8.93 | K37: =K29/30 -> 9.77 | L37: =L29/30 -> 10.7 | M37: =M29/30 -> 11.5 | N37: =N29/30 -> 12.223333 | O37: =O29/30 -> 12.923333 | P37: =P29/30 -> 13.646667 | Q37: =Q29/30 -> 14.37
H38: Lote 3 | I38: =I30/30 -> 9 | J38: =J30/30 -> 9.93 | K38: =K30/30 -> 10.77 | L38: =L30/30 -> 11.7 | M38: =M30/30 -> 12.5 | N38: =N30/30 -> 13.223333 | O38: =O30/30 -> 13.923333 | P38: =P30/30 -> 14.646667
G41: A Planilha de gasto nutricional vai ser informado pelo cliente e deve ser conter o gasto
G42: em reais por animal/cabeça/dia, valor da diária.
G43: Segue exemplo: | H43: GASTO NUTRICIONAL (R$/dia)
I44: Mês 1 | J44: Mês 2 | K44: Mês 3 | L44: Mês 4 | M44: Mês 5 | N44: Mês 6 | O44: Mês 7 | P44: Mês 8 | Q44: Mês 9 | R44: Mês 10 | S44: Mês 11
I45: Jan | J45: Fev | K45: Mar | L45: Abr | M45: Mai | N45: Jun | O45: Jul | P45: Ago | Q45: Set | R45: Out | S45: Nov
H46: Dias | I46: 31 | J46: 28 | K46: 31 | L46: 30 | M46: 31 | N46: 30 | O46: 31 | P46: 31 | Q46: 30 | R46: 31 | S46: 30
H47: Lote 1 | I47: 1 | J47: 1.2 | K47: 1.2 | L47: 1.5 | M47: 2 | N47: 2.5 | O47: 3.5 | P47: 4.5 | Q47: 15 | R47: 15 | S47: 15
H48: Lote 2 | I48: 1 | J48: 1.2 | K48: 1.2 | L48: 1.5 | M48: 2 | N48: 2.5 | O48: 3.5 | P48: 4.5 | Q48: 15 | R48: 15 | S48: 15
H49: Lote 3 | I49: 1 | J49: 1.2 | K49: 1.2 | L49: 1.5 | M49: 2 | N49: 2.5 | O49: 3.5 | P49: 15 | Q49: 15 | R49: 15
...

Sheet Dados de Faturamento
J2: FATURAMETO VIA CONFINAMENTO - ANIMAL TERMINADO | R2: FATURAMETO VIA VENDA DE ANIMAL NÃO TERMINADO
D4: Os Dados de Faturamento devem ser automatizados em função da forma de comercialização dos animais, sejam eles terminados ou não; Pode sofrer ajustes, mas não vai ter uma rotina maior do que MENSAL | J4: Essa deve ser uma planilha bem automatizada com as amarraçõs vindas principalmente dos dados de produção | K4: GANHO DE PESO NO CONFINAMENTO (KG) P/1,5 GMD | R4: FATURAMENTO COM ÁGIO DE 5%
K5: 1.5 | L5: Mês 0 | M5: Mês 1 | N5: Mês 2 | O5: Mês 3 | P5: Mês 4
L6: Entrada | M6: Ago | N6: Set | O6: Out | P6: Nov | R6: Lote | S6: Valor da @ | T6: Faturamento
M7: 31 | N7: 30 | O7: 31 | P7: 30 | R7: Lote 3 | S7: =L42*105% -> 367.5 | T7: =S7*(L26*'Dados de Prod'!K10) -> 1614795
K8: Lote 3 | L8: ='Dados de Prod'!P30 -> 439.4 | M8: =$K$5*M7 -> 46.5 | N8: =$K$5*N7 -> 45 | O8: =$K$5*O7 -> 46.5 | R8: Lote 2 | S8: =L43*105% -> 357 | T8: =S8*(L27*'Dados de Prod'!K9) -> 2565045
K9: Lote 2 | L9: ='Dados de Prod'!Q29 -> 431.1 | N9: =$K$5*N7 -> 45 | O9: =$K$5*O7 -> 46.5 | P9: =$K$5*P7 -> 45 | R9: Lote 1 | S9: =L44*105% -> 357 | T9: =S9*(L28*'Dados de Prod'!K8) -> 954618
K10: Lote 1 | L10: ='Dados de Prod'!Q28 -> 401.1 | N10: =$K$5*N7 -> 45 | O10: =$K$5*O7 -> 46.5 | P10: =$K$5*P7 -> 45 | T10: =SUM(T7:T9) -> 5134458
J13: O GMD será informado pelo cliente/responsável, nesse exemplo foi de 1,5 | K13: EVOLUÇÃO DO PESO NO CONFINAMENTO (KG) | R13: Foi convencionado um ágio de 5% sobre o valor da @, para a venda dos animais
K14: 1.5 | L14: Mês 0 | M14: Mês 1 | N14: Mês 2 | O14: Mês 3 | P14: Mês 4
L15: Entrada | M15: Ago | N15: Set | O15: Out | P15: Nov
M16: 31 | N16: 30 | O16: 31 | P16: 30
K17: Lote 3 | L17: =L8 -> 439.4 | M17: =L17+M8 -> 485.9 | N17: =M17+N8 -> 530.9 | O17: =N17+O8 -> 577.4
K18: Lote 2 | L18: =L9 -> 431.1 | M18: =M9/30 -> 0 | N18: =L18+N9 -> 476.1 | O18: =N18+O9 -> 522.6 | P18: =O18+P9 -> 567.6
K19: Lote 1 | L19: =L10 -> 401.1 | M19: =M10/30 -> 0 | N19: =L19+N10 -> 446.1 | O19: =N19+O10 -> 492.6 | P19: =O19+P10 -> 537.6
K22: EVOLUÇÃO DO PESO NO CONFINAMENTO (@)
K23: 1.5 | L23: Mês 0 | M23: Mês 1 | N23: Mês 2 | O23: Mês 3 | P23: Mês 4
L24: Entrada | M24: Ago | N24: Set | O24: Out | P24: Nov
M25: 31 | N25: 30 | O25: 31 | P25: 30
K26: Lote 3 | L26: =L17/30 -> 14.646667 | M26: =M17/30 -> 16.196667 | N26: =N17/30 -> 17.696667 | O26: =O17/30 -> 19.246667
K27: Lote 2 | L27: =L18/30 -> 14.37 | M27: =M18/30 -> 0 | N27: =N18/30 -> 15.87 | O27: =O18/30 -> 17.42 | P27: =P18/30 -> 18.92
K28: Lote 1 | L28: =L19/30 -> 13.37 | M28: =M19/30 -> 0 | N28: =N19/30 -> 14.87 | O28: =O19/30 -> 16.42 | P28: =P19/30 -> 17.92
J31: O Rendimento de carcaça será informado pelo cliente/responsável, nesse exemplo foi de 55% | K31: RENDIMENTO 55% | O31: QUANT. DE @/LOTE
K33: Lote 3 | L33: =(O17*55%)/15 -> 21.171333 | O33: Lote 3 | P33: =L33*'Dados de Prod'!K10 -> 6351.4
K34: Lote 2 | L34: =(P18*55%)/15 -> 20.812 | O34: Lote 2 | P34: =L34*'Dados de Prod'!K9 -> 10406
K35: Lote 1 | L35: =(P19*55%)/15 -> 19.712 | O35: Lote 1 | P35: =L35*'Dados de Prod'!K8 -> 3942.4
P36: =SUM(P33:P35) -> 20699.8
J39: O valor por @ no estágio de projeção será sugerido e depois será identificado pela efetivação da comrcialização | K39: FATURAMENTO
J41: Os valores faturados vão ser utilizados no fluxo de caixa | K41: Lote | L41: Valor da @ | M41: Faturamento
K42: Lote 3 | L42: 350 | M42: =L42*P33 -> 2222990
K43: Lote 2 | L43: 340 | M43: =L43*P34 -> 3538040
K44: Lote 1 | L44: 340 | M44: =L44*P35 -> 1340416
M45: =SUM(M42:M44) -> 7101446

Sheet Fluxo
I1: FLUXO P/ 3 ANOS | J1: 0 | K1: 46023 | L1: 46054 | M1: 46082 | N1: 46113 | O1: 46143 | P1: 46174 | Q1: 46204 | R1: 46235 | S1: 46266 | T1: 46296 | U1: 46327
K2: 1 | L2: 2 | M2: 3 | N2: 4 | O2: 5 | P2: 6 | Q2: 7 | R2: 8 | S2: 9 | T2: 10 | U2: 11
B3: Aqui temos uma sugestão de Fluxo de Caixa, ele deve ser automatizado com as informações oriundas da produçao e do faturamento; O cliente/responsável deve inicialmente preencher as rúbricas de custo fixo considerando o período mês a mês; Ele deve fazer uma projeção de gastos com custo fixo, e ter um horizonte projetado de pelo menos 01 ano; Ele deve preencher em um ambiente específico e não no fluxo, depois do preenchimento do projetado ele pode vizualizar no fluxo que já estará automatizado. | I3: INVESTIMENTOS | J3: =-J5-K4 -> -3227000
I4: CAPITAL DE GIRO | X4: =I3 -> INVESTIMENTOS | Y4: =-J3 -> 3227000
I5: Aquisição de Animais | J5: =(Produção!T5*Produção!Q5)+(Produção!T6*Produção!Q6)+(Produção!T7*Produção!Q7) -> 3227000 | X5: =I14 -> CUSTOS FIXOS | Y5: =SUM(K14:U14) -> 662200
I6: RECEITAS | K6: =SUM(K7:K13) -> 0 | L6: =SUM(L7:L13) -> 0 | M6: =SUM(M7:M13) -> 0 | N6: =SUM(N7:N13) -> 0 | O6: =SUM(O7:O13) -> 0 | P6: =SUM(P7:P13) -> 0 | Q6: =SUM(Q7:Q13) -> 0 | R6: =SUM(R7:R13) -> 0 | ... U6: =SUM(U7:U13) -> 4878456 | X6: =I28 -> CUSTOS VARIÁVEIS | Y6: =SUM(K28:U28) -> 2055580.6
I7: Venda de Vacas | X7: Desembolso | Y7: =Y4+Y5+Y6 -> 5944780.7
I8: Venda de Bois | T8: ='Dados de Faturamento'!M42 -> 2222990 | U8: ='Dados de Faturamento'!M43+'Dados de Faturamento'!M44 -> 4878456 | X8: FATURAMENTO | Y8: =SUM(T8:U8) -> 7101446
I9: Vendas de Novilhas | X9: RESULTADO | Y9: =Y8-Y7 -> 1156665.3
I10: Venda de Bezerras | X10: RENTABILIDADE | Y10: =Y9/(Y4+Y5+Y6) -> 0.19456821
I11: Venda de Bezerros | X11: LUCRATIVIDADE | Y11: =Y9/Y8 -> 0.16287744
I12: Venda de Garrote
I13: Venda de Silagem
I14: CUSTOS FIXOS | K14: =SUM(K15:K27) -> 60200 | L14: =SUM(L15:L27) -> 60200 | M14: =SUM(M15:M27) -> 60200 | N14: =SUM(N15:N27) -> 60200 | O14: =SUM(O15:O27) -> 60200 | P14: =SUM(P15:P27) -> 60200 | Q14: =SUM(Q15:Q27) -> 60200 | R14: =SUM(R15:R27) -> 60200 | ... U14: =SUM(U15:U27) -> 60200
B15: Esse fluxo está considerando o faturamento com a comercialização do animais confinados. | I15: Arrendamento | K15: 5000 | L15: 5000 | M15: 5000 | N15: 5000 | O15: 5000 | P15: 5000 | Q15: 5000 | R15: 5000 | S15: 5000 | T15: 5000 | U15: 5000
I16: Amortização | K16: 5000 | L16: 5000 | M16: 5000 | N16: 5000 | O16: 5000 | P16: 5000 | Q16: 5000 | R16: 5000 | S16: 5000 | T16: 5000 | U16: 5000
I17: Prólabore | K17: 20000 | L17: 20000 | M17: 20000 | N17: 20000 | O17: 20000 | P17: 20000 | Q17: 20000 | R17: 20000 | S17: 20000 | T17: 20000 | U17: 20000
I18: Manutenção | K18: 3000 | L18: 3000 | M18: 3000 | N18: 3000 | O18: 3000 | P18: 3000 | Q18: 3000 | R18: 3000 | S18: 3000 | T18: 3000 | U18: 3000
I19: Combustível | K19: 2000 | L19: 2000 | M19: 2000 | N19: 2000 | O19: 2000 | P19: 2000 | Q19: 2000 | R19: 2000 | S19: 2000 | T19: 2000 | U19: 2000
I20: Mão de Obra | K20: 15000 | L20: 15000 | M20: 15000 | N20: 15000 | O20: 15000 | P20: 15000 | Q20: 15000 | R20: 15000 | S20: 15000 | T20: 15000 | U20: 15000
I21: Serviços Técnicos | K21: 5000 | L21: 5000 | M21: 5000 | N21: 5000 | O21: 5000 | P21: 5000 | Q21: 5000 | R21: 5000 | S21: 5000 | T21: 5000 | U21: 5000
I22: Supermercado | K22: 1000 | L22: 1000 | M22: 1000 | N22: 1000 | O22: 1000 | P22: 1000 | Q22: 1000 | R22: 1000 | S22: 1000 | T22: 1000 | U22: 1000
I23: ITR | K23: 2000 | L23: 2000 | M23: 2000 | N23: 2000 | O23: 2000 | P23: 2000 | Q23: 2000 | R23: 2000 | S23: 2000 | T23: 2000 | U23: 2000
I24: Fretes | K24: 500 | L24: 500 | M24: 500 | N24: 500 | O24: 500 | P24: 500 | Q24: 500 | R24: 500 | S24: 500 | T24: 500 | U24: 500
I25: Energia | K25: 500 | L25: 500 | M25: 500 | N25: 500 | O25: 500 | P25: 500 | Q25: 500 | R25: 500 | S25: 500 | T25: 500 | U25: 500
I26: Tele/Internet | K26: 200 | L26: 200 | M26: 200 | N26: 200 | O26: 200 | P26: 200 | Q26: 200 | R26: 200 | S26: 200 | T26: 200 | U26: 200
I27: Contador | K27: 1000 | L27: 1000 | M27: 1000 | N27: 1000 | O27: 1000 | P27: 1000 | Q27: 1000 | R27: 1000 | S27: 1000 | T27: 1000 | U27: 1000
I28: CUSTOS VARIÁVEIS | K28: =K29+K30+K31+K32 -> 31310 | L28: =L29+L30+L31+L32 -> 33936 | M28: =M29+M30+M31+M32 -> 37572 | N28: =N29+N30+N31+N32 -> 45450 | O28: =O29+O30+O31+O32 -> 62620 | P28: =P29+P30+P31+P32 -> 75750 | Q28: =Q29+Q30+Q31+Q32 -> 109585 | R28: =R29+R30+R31+R32 -> 239521.5 | ... U28: =U29+U30+U31+U32 -> 440111.4
I29: Alimentação/Suplem. | K29: ='Dados de Prod'!I68 -> 31000 | L29: ='Dados de Prod'!J68 -> 33600 | M29: ='Dados de Prod'!K68 -> 37200 | N29: ='Dados de Prod'!L68 -> 45000 | O29: ='Dados de Prod'!M68 -> 62000 | P29: ='Dados de Prod'!N68 -> 75000 | Q29: ='Dados de Prod'!O68 -> 108500 | R29: ='Dados de Prod'!P68 -> 237150 | ... U29: ='Dados de Prod'!S68 -> 315000
I30: Sanitário/Med 2% | K30: =K29*1% -> 310 | L30: =L29*1% -> 336 | M30: =M29*1% -> 372 | N30: =N29*1% -> 450 | O30: =O29*1% -> 620 | P30: =P29*1% -> 750 | Q30: =Q29*1% -> 1085 | R30: =R29*1% -> 2371.5 | ... U30: =U29*1% -> 3150
I31: Serviços/Outros | K31: =K6*1% -> 0 | L31: =L6*1% -> 0 | M31: =M6*1% -> 0 | N31: =N6*1% -> 0 | O31: =O6*1% -> 0 | P31: =P6*1% -> 0 | Q31: =Q6*1% -> 0 | R31: =R6*1% -> 0 | ... U31: =U6*1% -> 48784.56
I32: Impostos | K32: =K6*1.5% -> 0 | L32: =L6*1.5% -> 0 | M32: =M6*1.5% -> 0 | N32: =N6*1.5% -> 0 | O32: =O6*1.5% -> 0 | P32: =P6*1.5% -> 0 | Q32: =Q6*1.5% -> 0 | R32: =R6*1.5% -> 0 | ... U32: =U6*1.5% -> 73176.84
I33: FLUXO DE CAIXA LIVRE | J33: =J3 -> -3227000 | K33: =(K6+K4)-(K3+K14+K28) -> -91510 | L33: =(L6+L4)-(L3+L14+L28) -> -94136 | M33: =(M6+M4)-(M3+M14+M28) -> -97772 | N33: =(N6+N4)-(N3+N14+N28) -> -105650 | O33: =(O6+O4)-(O3+O14+O28) -> -122820 | P33: =(P6+P4)-(P3+P14+P28) -> -135950 | Q33: =(Q6+Q4)-(Q3+Q14+Q28) -> -169785 | R33: =(R6+R4)-(R3+R14+R28) -> -299721.5 | ... U33: =(U6+U4)-(U3+U14+U28) -> 4378144.6
I34: FLUXO DE CAIXA ACUM | J34: =J33 -> -3227000 | K34: =J34+K33 -> -3318510 | L34: =K34+L33 -> -3412646 | M34: =L34+M33 -> -3510418 | N34: =M34+N33 -> -3616068 | O34: =N34+O33 -> -3738888 | P34: =O34+P33 -> -3874838 | Q34: =P34+Q33 -> -4044623 | R34: =Q34+R33 -> -4344344.5 | ... U34: =T34+U33 -> 1156665.3

Sheet PE LOTE 1
K4: MÊS 1 | L4: MÊS 2 | M4: MÊS 3 | N4: MÊS 4 | O4: MÊS 5 | P4: MÊS 6 | Q4: MÊS 7 | R4: MÊS 8 | S4: MÊS 9 | T4: MÊS 10 | U4: MÊS 11
K5: 46023 | L5: 46054 | M5: 46082 | N5: 46113 | O5: 46143 | P5: 46174 | Q5: 46204 | R5: 46235 | S5: 46266 | T5: 46296 | U5: 46327
J6: Quantidade | K6: =Produção!$Q$5 -> 200 | L6: =Produção!$Q$5 -> 200 | M6: =Produção!$Q$5 -> 200 | N6: =Produção!$Q$5 -> 200 | O6: =Produção!$Q$5 -> 200 | P6: =Produção!$Q$5 -> 200 | Q6: =Produção!$Q$5 -> 200 | R6: =Produção!$Q$5 -> 200 | ... U6: =Produção!$Q$5 -> 200
J8: Entrada | K8: 46023 | L8: =K9+1 -> 46054 | M8: =L9+1 -> 46082 | N8: =M9+1 -> 46113 | O8: =N9+1 -> 46143 | P8: =O9+1 -> 46174 | Q8: =P9+1 -> 46204 | R8: =Q9+1 -> 46235 | S8: =R9+1 -> 46266 | ... U8: =T9+1 -> 46327
J9: Saída | K9: =K8+K13 -> 46053 | L9: =L8+L13 -> 46081 | M9: =M8+M13 -> 46112 | N9: =N8+N13 -> 46142 | O9: =O8+O13 -> 46173 | P9: =P8+P13 -> 46203 | Q9: =Q8+Q13 -> 46234 | R9: =R8+R13 -> 46265 | ... U9: =U8+U13 -> 46356
E10: SIM, devem ir para o dashboard | I10: SIM | J10: Peso de Entrada @ | K10: =K11/30 -> 7 | L10: =L11/30 -> 7.9 | M10: =M11/30 -> 8.71 | N10: =N11/30 -> 9.61 | O10: =O11/30 -> 10.383333
I11: SIM | J11: Peso de Entrada Kg | K11: =Produção!R5 -> 210 | L11: =K12 -> 237 | M11: =L12 -> 261.3 | N11: =M12 -> 288.3 | O11: =N12 -> 311.5 | P11: =O12 -> 332.5 | Q11: =P12 -> 352.8 | R11: =Q12 -> 373.8 | S11: =R12 -> 394.8 | ... U11: =T12 -> 483.3
I12: SIM | J12: Peso de Saída (kg) | K12: =K11+K16 -> 237 | L12: =L11+L16 -> 261.3 | M12: =M11+M16 -> 288.3 | N12: =N11+N16 -> 311.5 | O12: =O11+O16 -> 332.5 | P12: =P11+P16 -> 352.8 | Q12: =Q11+Q16 -> 373.8 | R12: =R11+R16 -> 394.8 | ... U12: =U11+U16 -> 526.8
I13: NÃO | J13: Período (dias) | K13: 30 | L13: 27 | M13: 30 | N13: 29 | O13: 30 | P13: 29 | Q13: 30 | R13: 30 | S13: 29 | T13: 30 | U13: 29
I14: SIM | J14: Custo da Diária | K14: =Produção!AA7+((Fluxo!K14/30)/(Produção!$Q$5+Produção!$Q$6+Produção!$Q$7)) -> 3.0066667 | L14: =Produção!AB7+((Fluxo!L14/30)/(Produção!$Q$5+Produção!$Q$6+Produção!$Q$7)) -> 3.2066667 | M14: =Produção!AC7+((Fluxo!M14/30)/(Produção!$Q$5+Produção!$Q$6+Produção!$Q$7)) -> 3.2066667 | N14: =Produção!AD7+((Fluxo!N14/30)/(Produção!$Q$5+Produção!$Q$6+Produção!$Q$7)) -> 3.5066667 | O14: =Produção!AE7+((Fluxo!O14/30)/(Produção!$Q$5+Produção!$Q$6+Produção!$Q$7)) -> 4.0066667 | P14: =Produção!AF7+((Fluxo!P14/30)/(Produção!$Q$5+Produção!$Q$6+Produção!$Q$7)) -> 4.5066667 | Q14: =Produção!AG7+((Fluxo!Q14/30)/(Produção!$Q$5+Produção!$Q$6+Produção!$Q$7)) -> 5.5066667 | R14: =Produção!AH7+((Fluxo!R14/30)/(Produção!$Q$5+Produção!$Q$6+Produção!$Q$7)) -> 6.5066667 | S14: =Produção!AI7+((Fluxo!R14/30)/(Produção!$Q$5+Produção!$Q$6+Produção!$Q$7)) -> 17.006667 | T14: =Produção!AJ7+((Fluxo!S14/30)/(Produção!$Q$5+Produção!$Q$6+Produção!$Q$7)) -> 17.006667 | U14: =Produção!AK7+((Fluxo!T14/30)/(Produção!$Q$5+Produção!$Q$6+Produção!$Q$7)) -> 17.006667
I15: SIM | J15: Ganho de Peso Dia (Kg) | K15: =Produção!O13 -> 0.9 | L15: =Produção!P13 -> 0.9 | M15: =Produção!Q13 -> 0.9 | N15: =Produção!R13 -> 0.8 | O15: =Produção!S13 -> 0.7 | P15: =Produção!T13 -> 0.7 | Q15: =Produção!U13 -> 0.7 | R15: =Produção!V13 -> 0.7 | S15: 1.5 | T15: 1.5 | U15: 1.5
I16: NÃO | J16: Ganho de Peso Animal (Kg) | K16: =K15*K13 -> 27 | L16: =L15*L13 -> 24.3 | M16: =M15*M13 -> 27 | N16: =N15*N13 -> 23.2 | O16: =O15*O13 -> 21 | P16: =P15*P13 -> 20.3 | Q16: =Q15*Q13 -> 21 | R16: =R15*R13 -> 21 | ... U16: =U15*U13 -> 43.5
I17: NÃO | J17: Custo por @ | K17: =(K19+(K14*K13))/K22 -> 374.70886 | L17: =(L19+(L14*L13))/L22 -> 349.80253 | M17: =(M19+(M14*M13))/M22 -> 327.05307 | N17: =(N19+(N14*N13))/N22 -> 312.4886 | O17: =(O19+(O14*O13))/O22 -> 303.59759 | P17: =(P19+(P14*P13))/P22 -> 297.24206 | Q17: =(Q19+(Q14*Q13))/Q22 -> 293.8015 | R17: =(R19+(R14*R13))/R22 -> 293.00659 | ... U17: =(U19+(U14*U13))/U22 -> 277.10465
I18: NÃO | J18: Custo por Lote | K18: =(K14*K6)*K13 -> 18040 | L18: =(L14*L6)*L13 -> 17316 | M18: =(M14*M6)*M13 -> 19240 | N18: =(N14*N6)*N13 -> 20338.667 | O18: =(O14*O6)*O13 -> 24040 | P18: =(P14*P6)*P13 -> 26138.667 | Q18: =(Q14*Q6)*Q13 -> 33040 | R18: =(R14*R6)*R13 -> 39040 | ... U18: =(U14*U6)*U13 -> 98638.667
I19: NÃO | J19: Valor do Animal | K19: =Produção!T5 -> 2870 | L19: =K28/L6 -> 2960.2 | M19: =L28/M6 -> 3046.78 | N19: =M28/N6 -> 3142.98 | O19: =N28/O6 -> 3244.6733 | P19: =O28/P6 -> 3364.8733 | Q19: =P28/Q6 -> 3495.5667 | R19: =Q28/R6 -> 3660.7667 | S19: =R28/S6 -> 3855.9667 | ... U19: =T28/U6 -> 4859.36
I20: NÃO | J20: Rendimento | K20: 0.5 | L20: 0.5 | M20: 0.5 | N20: 0.5 | O20: 0.5 | P20: 0.5 | Q20: 0.5 | R20: 0.5 | S20: 0.5 | T20: 0.5 | U20: 0.55
I21: NÃO | J21: Ganho de Peso @ | K21: =(K16*K20)/15 -> 0.9 | L21: =(L16*L20)/15 -> 0.81 | M21: =(M16*M20)/15 -> 0.9 | N21: =(N16*N20)/15 -> 0.77333333 | O21: =(O16*O20)/15 -> 0.7 | P21: =(P16*P20)/15 -> 0.67666667 | Q21: =(Q16*Q20)/15 -> 0.7 | R21: =(R16*R20)/15 -> 0.7 | ... U21: =(U16*U20)/15 -> 1.595
I22: NÃO | J22: Total de @ Animal | K22: =(K12*K20)/15 -> 7.9 | L22: =(L12*L20)/15 -> 8.71 | M22: =(M12*M20)/15 -> 9.61 | N22: =(N12*N20)/15 -> 10.383333 | O22: =(O12*O20)/15 -> 11.083333 | P22: =(P12*P20)/15 -> 11.76 | Q22: =(Q12*Q20)/15 -> 12.46 | R22: =(R12*R20)/15 -> 13.16 | ... U22: =(U12*U20)/15 -> 19.316
I23: NÃO | J23: Mortalidade | K23: 0 | L23: 0 | M23: 0 | N23: 0 | O23: 0 | P23: 0 | Q23: 0 | R23: 0 | S23: 0 | T23: 0 | U23: 0
I24: NÃO | J24: Total de @ | K24: =(K6-(K6*K23))*K22 -> 1580 | L24: =(L6-(L6*L23))*L22 -> 1742 | M24: =(M6-(M6*M23))*M22 -> 1922 | N24: =(N6-(N6*N23))*N22 -> 2076.6667 | O24: =(O6-(O6*O23))*O22 -> 2216.6667 | P24: =(P6-(P6*P23))*P22 -> 2352 | Q24: =(Q6-(Q6*Q23))*Q22 -> 2492 | R24: =(R6-(R6*R23))*R22 -> 2632 | ... U24: =(U6-(U6*U23))*U22 -> 3863.2
I25: NÃO | J25: Invest Animais | K25: =K6*K19 -> 574000 | L25: =L6*L19 -> 592040 | M25: =M6*M19 -> 609356 | N25: =N6*N19 -> 628596 | O25: =O6*O19 -> 648934.67 | P25: =P6*P19 -> 672974.67 | Q25: =Q6*Q19 -> 699113.33 | R25: =R6*R19 -> 732153.33 | ... U25: =U6*U19 -> 971872
I26: NÃO | J26: Invest Alimentação | K26: =K6*K13*K14 -> 18040 | L26: =L6*L13*L14 -> 17316 | M26: =M6*M13*M14 -> 19240 | N26: =N6*N13*N14 -> 20338.667 | O26: =O6*O13*O14 -> 24040 | P26: =P6*P13*P14 -> 26138.667 | Q26: =Q6*Q13*Q14 -> 33040 | R26: =R6*R13*R14 -> 39040 | ... U26: =U6*U13*U14 -> 98638.667
I27: NÃO | J27: Custo de Capital-CDI
I28: NÃO | J28: Investimento Total | K28: =K25+K26+K27 -> 592040 | L28: =L25+L26+L27 -> 609356 | M28: =M25+M26+M27 -> 628596 | N28: =N25+N26+N27 -> 648934.67 | O28: =O25+O26+O27 -> 672974.67 | P28: =P25+P26+P27 -> 699113.33 | Q28: =Q25+Q26+Q27 -> 732153.33 | R28: =R25+R26+R27 -> 771193.33 | ... U28: =U25+U26+U27 -> 1070510.7
I29: SIM | J29: Ponto de Equilíbrio @ | K29: =(K28/K24) -> 374.70886 | L29: =L28/L24 -> 349.80253 | M29: =M28/M24 -> 327.05307 | N29: =N28/N24 -> 312.4886 | O29: =O28/O24 -> 303.59759 | P29: =P28/P24 -> 297.24206 | Q29: =Q28/Q24 -> 293.8015 | R29: =R28/R24 -> 293.00659 | S29: =S28/S24 -> 297.68378 | ... U29: =U28/U24 -> 277.10465
I30: NÃO | J30: Peso do Animal | K30: =K25/K28 -> 0.96952909 | L30: =L25/L28 -> 0.97158311 | M30: =M25/M28 -> 0.96939211 | N30: =N25/N28 -> 0.96865838 | O30: =O25/O28 -> 0.964278 | P30: =P25/P28 -> 0.96261169 | Q30: =Q25/Q28 -> 0.95487284 | R30: =R25/R28 -> 0.94937716 | ... U30: =U25/U28 -> 0.90785831
I31: NÃO | J31: Peso da Produção | K31: =K26/K28 -> 0.030470914 | L31: =L26/L28 -> 0.028416886 | M31: =M26/M28 -> 0.030607894 | N31: =N26/N28 -> 0.031341625 | O31: =O26/O28 -> 0.035721998 | P31: =P26/P28 -> 0.037388311 | Q31: =Q26/Q28 -> 0.045127159 | R31: =R26/R28 -> 0.050622844 | ... U31: =U26/U28 -> 0.092141694
I32: NÃO | J32: Peso do Custo de Capital | K32: =K27/K28 -> 0 | L32: =L27/L28 -> 0 | M32: =M27/M28 -> 0 | N32: =N27/N28 -> 0 | O32: =O27/O28 -> 0 | P32: =P27/P28 -> 0 | Q32: =Q27/Q28 -> 0 | R32: =R27/R28 -> 0 | ... U32: =U27/U28 -> 0
I33: NÃO | J33: Cotação B3 | U33: 350
I34: NÃO | J34: Base da sua Região | U34: 0
I35: NÃO | J35: Cotação B3 - Base | K35: =K33-(K33*K34) -> 0 | L35: =L33-(L33*L34) -> 0 | M35: =M33-(M33*M34) -> 0 | N35: =N33-(N33*N34) -> 0 | O35: =O33-(O33*O34) -> 0 | P35: =P33-(P33*P34) -> 0 | Q35: =Q33-(Q33*Q34) -> 0 | R35: =R33-(R33*R34) -> 0 | ... U35: =U33-(U33*U34) -> 350
I36: NÃO | J36: Resultado p/ @ | K36: =K35-K29 -> -374.70886 | L36: =L35-L29 -> -349.80253 | M36: =M35-M29 -> -327.05307 | N36: =N35-N29 -> -312.4886 | O36: =O35-O29 -> -303.59759 | P36: =P35-P29 -> -297.24206 | Q36: =Q35-Q29 -> -293.8015 | R36: =R35-R29 -> -293.00659 | ... U36: =U35-U29 -> 72.895354
I37: NÃO | J37: Faturamento | K37: =(K24*K35) -> 0 | L37: =(L24*L35) -> 0 | M37: =(M24*M35) -> 0 | N37: =(N24*N35) -> 0 | O37: =(O24*O35) -> 0 | P37: =(P24*P35) -> 0 | Q37: =(Q24*Q35) -> 0 | R37: =(R24*R35) -> 0 | ... U37: =(U24*U35) -> 1352120
I38: NÃO | J38: Lucro Líquido na Operação | K38: =K37-K28 -> -592040 | L38: =L37-L28 -> -609356 | M38: =M37-M28 -> -628596 | N38: =N37-N28 -> -648934.67 | O38: =O37-O28 -> -672974.67 | P38: =P37-P28 -> -699113.33 | Q38: =Q37-Q28 -> -732153.33 | R38: =R37-R28 -> -771193.33 | ... U38: =U37-U28 -> 281609.33
I39: NÃO | J39: Lucro Líquido por Animal | K39: =K38/(K6-(K6*K23)) -> -2960.2 | L39: =L38/(L6-(L6*L23)) -> -3046.78 | M39: =M38/(M6-(M6*M23)) -> -3142.98 | N39: =N38/(N6-(N6*N23)) -> -3244.6733 | O39: =O38/(O6-(O6*O23)) -> -3364.8733 | P39: =P38/(P6-(P6*P23)) -> -3495.5667 | Q39: =Q38/(Q6-(Q6*Q23)) -> -3660.7667 | R39: =R38/(R6-(R6*R23)) -> -3855.9667 | ... U39: =U38/(U6-(U6*U23)) -> 1408.0467
I40: NÃO | J40: Taxa Líquida no Período | K40: =K38/K28 -> -1 | L40: =L38/L28 -> -1 | M40: =M38/M28 -> -1 | N40: =N38/N28 -> -1 | O40: =O38/O28 -> -1 | P40: =P38/P28 -> -1 | Q40: =Q38/Q28 -> -1 | R40: =R38/R28 -> -1 | ... U40: =U38/U28 -> 0.26306074
I41: NÃO | J41: Taxa Líquida ao Mês | K41: =((1+K40)^(1/(K13/30)))-1 -> -1 | L41: =((1+L40)^(1/(L13/30)))-1 -> -1 | M41: =((1+M40)^(1/(M13/30)))-1 -> -1 | N41: =((1+N40)^(1/(N13/30)))-1 -> -1 | O41: =((1+O40)^(1/(O13/30)))-1 -> -1 | P41: =((1+P40)^(1/(P13/30)))-1 -> -1 | Q41: =((1+Q40)^(1/(Q13/30)))-1 -> -1 | R41: =((1+R40)^(1/(R13/30)))-1 -> -1 | ... U41: =((1+U40)^(1/(U13/30)))-1 -> 0.27327328
I42: NÃO | J42: Taxa Líquida ao Ano | K42: =((1+K41)^12)-1 -> -1 | L42: =((1+L41)^12)-1 -> -1 | M42: =((1+M41)^12)-1 -> -1 | N42: =((1+N41)^12)-1 -> -1 | O42: =((1+O41)^12)-1 -> -1 | P42: =((1+P41)^12)-1 -> -1 | Q42: =((1+Q41)^12)-1 -> -1 | R42: =((1+R41)^12)-1 -> -1 | ... U42: =((1+U41)^12)-1 -> 17.157644

Sheet PE GLOBAL
G3: PONTO DE EQUILÍBRIO
U4: =G7 -> LOTE 1
G5: LOTES | H5: MÊS 1 | I5: MÊS 2 | J5: MÊS 3 | K5: MÊS 4 | L5: MÊS 5 | M5: MÊS 6 | N5: MÊS 7 | O5: MÊS 8 | P5: MÊS 9 | Q5: MÊS 10 | R5: MÊS 11 | U5: 46023 | V5: 374.70886
H6: 46023 | I6: 46054 | J6: 46082 | K6: 46113 | L6: 46143 | M6: 46174 | N6: 46204 | O6: 46235 | P6: 46266 | Q6: 46296 | R6: 46327 | U6: 46054 | V6: 349.80253
G7: LOTE 1 | H7: ='PE LOTE 1'!K29 -> 374.70886 | I7: ='PE LOTE 1'!L29 -> 349.80253 | J7: ='PE LOTE 1'!M29 -> 327.05307 | K7: ='PE LOTE 1'!N29 -> 312.4886 | L7: ='PE LOTE 1'!O29 -> 303.59759 | M7: ='PE LOTE 1'!P29 -> 297.24206 | N7: ='PE LOTE 1'!Q29 -> 293.8015 | O7: ='PE LOTE 1'!R29 -> 293.00659 | ... R7: ='PE LOTE 1'!U29 -> 277.10465 | U7: 46082 | V7: 327.05307
G8: LOTE 2 | H8: ='PE LOTE 2'!H29 -> 378.11587 | I8: ='PE LOTE 2'!I29 -> 351.73082 | J8: ='PE LOTE 2'!J29 -> 331.95513 | K8: ='PE LOTE 2'!K29 -> 317.19477 | L8: ='PE LOTE 2'!L29 -> 308.65623 | M8: ='PE LOTE 2'!M29 -> 302.05112 | N8: ='PE LOTE 2'!N29 -> 298.58777 | O8: ='PE LOTE 2'!O29 -> 297.57366 | ... R8: ='PE LOTE 2'!R29 -> 280.05258 | U8: 46113 | V8: 312.4886
G9: LOTE 3 | H9: ='PE LOTE 3'!H29 -> 371.04258 | I9: ='PE LOTE 3'!I29 -> 347.77904 | J9: ='PE LOTE 3'!J29 -> 330.02924 | K9: ='PE LOTE 3'!K29 -> 316.60632 | L9: ='PE LOTE 3'!L29 -> 308.76019 | M9: ='PE LOTE 3'!M29 -> 302.63346 | N9: ='PE LOTE 3'!N29 -> 299.38304 | O9: ='PE LOTE 3'!O29 -> 319.99248 | ... R9: ='PE LOTE 3'!R29 -> 0 | U9: 46143 | V9: 303.59759
U10: 46174 | V10: 297.24206
U11: 46204 | V11: 293.8015
G12: CUSTO DA @ PRODUZIDA | U12: 46235 | V12: 293.00659
U13: 46266 | V13: 297.68378
G14: LOTES | H14: MÊS 1 | I14: MÊS 2 | J14: MÊS 3 | K14: MÊS 4 | L14: MÊS 5 | M14: MÊS 6 | N14: MÊS 7 | O14: MÊS 8 | P14: MÊS 9 | Q14: MÊS 10 | R14: MÊS 11 | S14: MÉDIA @ PROD | U14: 46296 | V14: 301.63625
H15: 46023 | I15: 46054 | J15: 46082 | K15: 46113 | L15: 46143 | M15: 46174 | N15: 46204 | O15: 46235 | P15: 46266 | Q15: 46296 | R15: 46327 | U15: 46327 | V15: 277.10465
G16: LOTE 1 | H16: =('PE LOTE 1'!K26/'PE LOTE 1'!K6)/'PE LOTE 1'!K21 -> 100.22222 | I16: =('PE LOTE 1'!L26/'PE LOTE 1'!L6)/'PE LOTE 1'!L21 -> 106.88889 | J16: =('PE LOTE 1'!M26/'PE LOTE 1'!M6)/'PE LOTE 1'!M21 -> 106.88889 | K16: =('PE LOTE 1'!N26/'PE LOTE 1'!N6)/'PE LOTE 1'!N21 -> 131.5 | L16: =('PE LOTE 1'!O26/'PE LOTE 1'!O6)/'PE LOTE 1'!O21 -> 171.71429 | M16: =('PE LOTE 1'!P26/'PE LOTE 1'!P6)/'PE LOTE 1'!P21 -> 193.14286 | N16: =('PE LOTE 1'!Q26/'PE LOTE 1'!Q6)/'PE LOTE 1'!Q21 -> 236 | O16: =('PE LOTE 1'!R26/'PE LOTE 1'!R6)/'PE LOTE 1'!R21 -> 278.85714 | ... R16: =('PE LOTE 1'!U26/'PE LOTE 1'!U6)/'PE LOTE 1'!U21 -> 309.21212 | S16: =AVERAGE(H16:R16) -> 210.42664
G17: LOTE 2 | H17: =('PE LOTE 2'!H26/'PE LOTE 2'!H6)/'PE LOTE 2'!H21 -> 100.22222 | I17: =('PE LOTE 2'!I26/'PE LOTE 2'!I6)/'PE LOTE 2'!I21 -> 106.88889 | J17: =('PE LOTE 2'!J26/'PE LOTE 2'!J6)/'PE LOTE 2'!J21 -> 106.88889 | K17: =('PE LOTE 2'!K26/'PE LOTE 2'!K6)/'PE LOTE 2'!K21 -> 131.5 | L17: =('PE LOTE 2'!L26/'PE LOTE 2'!L6)/'PE LOTE 2'!L21 -> 171.71429 | M17: =('PE LOTE 2'!M26/'PE LOTE 2'!M6)/'PE LOTE 2'!M21 -> 193.14286 | N17: =('PE LOTE 2'!N26/'PE LOTE 2'!N6)/'PE LOTE 2'!N21 -> 236 | O17: =('PE LOTE 2'!O26/'PE LOTE 2'!O6)/'PE LOTE 2'!O21 -> 278.85714 | ... R17: =('PE LOTE 2'!R26/'PE LOTE 2'!R6)/'PE LOTE 2'!R21 -> 309.21212 | S17: =AVERAGE(H17:R17) -> 210.42664
G18: LOTE 3 | H18: =('PE LOTE 3'!H26/'PE LOTE 3'!H6)/'PE LOTE 3'!H21 -> 100.22222 | I18: =('PE LOTE 3'!I26/'PE LOTE 3'!I6)/'PE LOTE 3'!I21 -> 106.88889 | J18: =('PE LOTE 3'!J26/'PE LOTE 3'!J6)/'PE LOTE 3'!J21 -> 106.88889 | K18: =('PE LOTE 3'!K26/'PE LOTE 3'!K6)/'PE LOTE 3'!K21 -> 131.5 | L18: =('PE LOTE 3'!L26/'PE LOTE 3'!L6)/'PE LOTE 3'!L21 -> 171.71429 | M18: =('PE LOTE 3'!M26/'PE LOTE 3'!M6)/'PE LOTE 3'!M21 -> 193.14286 | N18: =('PE LOTE 3'!N26/'PE LOTE 3'!N6)/'PE LOTE 3'!N21 -> 236 | O18: =('PE LOTE 3'!O26/'PE LOTE 3'!O6)/'PE LOTE 3'!O21 -> 728.85714 | ... Q18: =('PE LOTE 3'!Q26/'PE LOTE 3'!Q6)/'PE LOTE 3'!Q21 -> 309.21212 | S18: =AVERAGE(H18:Q18) -> 242.45597
U19: LOTE 1
U20: 46023 | V20: 100.22222
G21: Duas informações que devem estar no Dashboard, não no formato de planilha, mas no formato de gráficos e pode ser um a um, lote a lote | U21: 46054 | V21: 106.88889
U22: 46082 | V22: 106.88889
U23: 46113 | V23: 131.5
U24: 46143 | V24: 171.71429
U25: 46174 | V25: 193.14286
U26: 46204 | V26: 236
U27: 46235 | V27: 278.85714
U28: 46266 | V28: 340.13333
U29: 46296 | V29: 340.13333
U30: 46327 | V30: 309.21212

Sheet Produção
B2: Área Últil de Pastagem em (ha) | C2: 300 | D2: Dez | E2: Jan | F2: Fev | G2: Mar | H2: Abr | I2: Mai | J2: Jun | K2: Jul | L2: Ago
B3: Quantidade de Animais | C3: =Q5+Q6+Q7 -> 1000 | D3: Mês 0 | E3: Mês 1 | F3: Mês 2 | G3: Mês 3 | H3: Mês 4 | I3: Mês 5 | J3: Mês 6 | K3: Mês 7 | L3: Mês 8 | N3: HISTÓRICO DO PLANTEL | Z3: GASTO NUTRICIONAL (R$/dia)
B4: Evolução de Peso dos Animais | C4: =Q5+Q6+Q7 -> 1000 | D4: =(O22*$Q$5)+(O23*$Q$6)+(O24*$Q$7) -> 243000 | E4: =(P22*$Q$5)+(P23*$Q$6)+(P24*$Q$7) -> 270900 | F4: =(Q22*$Q$5)+(Q23*$Q$6)+(Q24*$Q$7) -> 296100 | G4: =(R22*$Q$5)+(R23*$Q$6)+(R24*$Q$7) -> 324000 | H4: =(S22*$Q$5)+(S23*$Q$6)+(S24*$Q$7) -> 348000 | I4: =(T22*$Q$5)+(T23*$Q$6)+(T24*$Q$7) -> 369700 | J4: =(U22*$Q$5)+(U23*$Q$6)+(U24*$Q$7) -> 390700 | K4: =(V22*$Q$5)+(V23*$Q$6)+(V24*$Q$7) -> 412400 | L4: =(W22*$Q$5)+(W23*$Q$6)+(W24*$Q$7) -> 295770 | O4: Sexo | P4: Idade (m) | Q4: Quant. | R4: Peso kg | S4: Peso @ | T4: Valor de Compra | AA4: Mês 1 | AB4: Mês 2 | AC4: Mês 3 | AD4: Mês 4 | AE4: Mês 5 | AF4: Mês 6 | AG4: Mês 7 | AH4: Mês 8 | AI4: Mês 9 | AJ4: Mês 10 | AK4: Mês 11
B5: Lotação | D5: =(D4/450)/$C$2 -> 1.8 | E5: =(E4/450)/$C$2 -> 2.0066667 | F5: =(F4/450)/$C$2 -> 2.1933333 | G5: =(G4/450)/$C$2 -> 2.4 | H5: =(H4/450)/$C$2 -> 2.5777778 | I5: =(I4/450)/$C$2 -> 2.7385185 | J5: =(J4/450)/$C$2 -> 2.8940741 | K5: =(K4/450)/$C$2 -> 3.0548148 | L5: =(L4/450)/$C$2 -> 2.1908889 | N5: Lote 1 | O5: M | P5: 10 | Q5: 200 | R5: 210 | S5: =R5/30 -> 7 | T5: =410*S5 -> 2870 | AA5: Dez | AB5: Jan | AC5: Fev | AD5: Mar | AE5: Abr | AF5: Mai | AG5: Jun | AH5: Jul | AI5: Ago | AJ5: Set | AK5: Out
N6: Lote 2 | O6: M | P6: 12 | Q6: 500 | R6: 240 | S6: =R6/30 -> 8 | T6: =400*S6 -> 3200 | Z6: Dias | AA6: 21 | AB6: 31 | AC6: 28 | AD6: 31 | AE6: 30 | AF6: 31 | AG6: 30 | AH6: 31 | AI6: 31 | AJ6: 30 | AK6: 31
N7: Lote 3 | O7: M | P7: 14 | Q7: 300 | R7: 270 | S7: =R7/30 -> 9 | T7: =390*S7 -> 3510 | Z7: Lote 1 | AA7: 1 | AB7: 1.2 | AC7: 1.2 | AD7: 1.5 | AE7: 2 | AF7: 2.5 | AG7: 3.5 | AH7: 4.5 | AI7: 15 | AJ7: 15 | AK7: 15
Z8: Lote 2 | AA8: 1 | AB8: 1.2 | AC8: 1.2 | AD8: 1.5 | AE8: 2 | AF8: 2.5 | AG8: 3.5 | AH8: 4.5 | AI8: 15 | AJ8: 15 | AK8: 15
Z9: Lote 3 | AA9: 1 | AB9: 1.2 | AC9: 1.2 | AD9: 1.5 | AE9: 2 | AF9: 2.5 | AG9: 3.5 | AH9: 15 | AI9: 15 | AJ9: 15
N10: PROJEÇÃO DE GANHO (kg)
O11: Mês 1 | P11: Mês 2 | Q11: Mês 3 | R11: Mês 4 | S11: Mês 5 | T11: Mês 6 | U11: Mês 7 | V11: Mês 8
O12: Jan | P12: Fev | Q12: Mar | R12: Abr | S12: Mai | T12: Jun | U12: Jul | V12: Ago | Z12: GASTO NUTRICIONAL POR ANIMAL (R$/mês)
N13: Lote 1 | O13: 0.9 | P13: 0.9 | Q13: 0.9 | R13: 0.8 | S13: 0.7 | T13: 0.7 | U13: 0.7 | V13: 0.7 | AA13: Mês 1 | AB13: Mês 2 | AC13: Mês 3 | AD13: Mês 4 | AE13: Mês 5 | AF13: Mês 6 | AG13: Mês 7 | AH13: Mês 8 | AI13: Mês 9 | AJ13: Mês 10 | AK13: Mês 11
N14: Lote 2 | O14: 0.9 | P14: 0.9 | Q14: 0.9 | R14: 0.8 | S14: 0.7 | T14: 0.7 | U14: 0.7 | V14: 0.7 | AA14: Dez | AB14: Jan | AC14: Fev | AD14: Mar | AE14: Abr | AF14: Mai | AG14: Jun | AH14: Jul | AI14: Ago | AJ14: Set | AK14: Out
N15: Lote 3 | O15: 0.9 | P15: 0.9 | Q15: 0.9 | R15: 0.8 | S15: 0.7 | T15: 0.7 | U15: 0.7 | V15: 0.7 | Z15: Dias | AA15: 21 | AB15: 31 | AC15: 28 | AD15: 31 | AE15: 30 | AF15: 31 | AG15: 30 | AH15: 31 | AI15: 31 | AJ15: 30 | AK15: 31
Z16: Lote 1 | AA16: =AA7*AA6 -> 21 | AB16: =AB7*AB6 -> 37.2 | AC16: =AC7*AC6 -> 33.6 | AD16: =AD7*AD6 -> 46.5 | AE16: =AE7*AE6 -> 60 | AF16: =AF7*AF6 -> 77.5 | AG16: =AG7*AG6 -> 105 | AH16: =AH7*AH6 -> 139.5 | ... AK16: =AK7*AK6 -> 465
Z17: Lote 2 | AA17: =AA8*AA6 -> 21 | AB17: =AB8*AB6 -> 37.2 | AC17: =AC8*AC6 -> 33.6 | AD17: =AD8*AD6 -> 46.5 | AE17: =AE8*AE6 -> 60 | AF17: =AF8*AF6 -> 77.5 | AG17: =AG8*AG6 -> 105 | AH17: =AH8*AH6 -> 139.5 | ... AK17: =AK8*AK6 -> 465
N18: EVOLUÇÃO DE PESO (kg) | Z18: Lote 3 | AA18: =AA9*AA6 -> 21 | AB18: =AB9*AB6 -> 37.2 | AC18: =AC9*AC6 -> 33.6 | AD18: =AD9*AD6 -> 46.5 | AE18: =AE9*AE6 -> 60 | AF18: =AF9*AF6 -> 77.5 | AG18: =AG9*AG6 -> 105 | AH18: =AH9*AH6 -> 465 | ... AJ18: =AJ9*AJ6 -> 450
O19: Mês 0 | P19: Mês 1 | Q19: Mês 2 | R19: Mês 3 | S19: Mês 4 | T19: Mês 5 | U19: Mês 6 | V19: Mês 7 | W19: Mês 8
O20: inicial | P20: Jan | Q20: Fev | R20: Mar | S20: Abr | T20: Mai | U20: Jun | V20: Jul | W20: Ago
N21: Dias | O21: 0 | P21: 31 | Q21: 28 | R21: 31 | S21: 30 | T21: 31 | U21: 30 | V21: 31 | W21: 31 | Z21: GASTO NUTRICIONAL POR LOTE (R$/mês)
N22: Lote 1 | O22: =R5 -> 210 | P22: =(O13*P21)+O22 -> 237.9 | Q22: =(P13*Q21)+P22 -> 263.1 | R22: =(Q13*R21)+Q22 -> 291 | S22: =(R13*S21)+R22 -> 315 | T22: =(S13*T21)+S22 -> 336.7 | U22: =(T13*U21)+T22 -> 357.7 | V22: =(U13*V21)+U22 -> 379.4 | W22: =(V13*W21)+V22 -> 401.1 | AA22: Mês 1 | AB22: Mês 2 | AC22: Mês 3 | AD22: Mês 4 | AE22: Mês 5 | AF22: Mês 6 | AG22: Mês 7 | AH22: Mês 8 | AI22: Mês 9 | AJ22: Mês 10 | AK22: Mês 11
N23: Lote 2 | O23: =R6 -> 240 | P23: =(O14*P21)+O23 -> 267.9 | Q23: =(P14*Q21)+P23 -> 293.1 | R23: =(Q14*R21)+Q23 -> 321 | S23: =(R14*S21)+R23 -> 345 | T23: =(S14*T21)+S23 -> 366.7 | U23: =(T14*U21)+T23 -> 387.7 | V23: =(U14*V21)+U23 -> 409.4 | W23: =(V14*W21)+V23 -> 431.1 | AA23: Dez | AB23: Jan | AC23: Fev | AD23: Mar | AE23: Abr | AF23: Mai | AG23: Jun | AH23: Jul | AI23: Ago | AJ23: Set | AK23: Out
N24: Lote 3 | O24: =R7 -> 270 | P24: =(O15*P21)+O24 -> 297.9 | Q24: =(P15*Q21)+P24 -> 323.1 | R24: =(Q15*R21)+Q24 -> 351 | S24: =(R15*S21)+R24 -> 375 | T24: =(S15*T21)+S24 -> 396.7 | U24: =(T15*U21)+T24 -> 417.7 | V24: =(U15*V21)+U24 -> 439.4 | Z24: Dias | AA24: 21 | AB24: 31 | AC24: 28 | AD24: 31 | AE24: 30 | AF24: 31 | AG24: 30 | AH24: 31 | AI24: 31 | AJ24: 30 | AK24: 31
Z25: Lote 1 | AA25: =AA16*$Q$5 -> 4200 | AB25: =AB16*$Q$5 -> 7440 | AC25: =AC16*$Q$5 -> 6720 | AD25: =AD16*$Q$5 -> 9300 | AE25: =AE16*$Q$5 -> 12000 | AF25: =AF16*$Q$5 -> 15500 | AG25: =AG16*$Q$5 -> 21000 | AH25: =AH16*$Q$5 -> 27900 | ... AK25: =AK16*$Q$5 -> 93000
Z26: Lote 2 | AA26: =AA17*$Q$6 -> 10500 | AB26: =AB17*$Q$6 -> 18600 | AC26: =AC17*$Q$6 -> 16800 | AD26: =AD17*$Q$6 -> 23250 | AE26: =AE17*$Q$6 -> 30000 | AF26: =AF17*$Q$6 -> 38750 | AG26: =AG17*$Q$6 -> 52500 | AH26: =AH17*$Q$6 -> 69750 | ... AK26: =AK17*$Q$6 -> 232500
N27: EVOLUÇÃO DE PESO (@) | Z27: Lote 3 | AA27: =AA18*$Q$7 -> 6300 | AB27: =AB18*$Q$7 -> 11160 | AC27: =AC18*$Q$7 -> 10080 | AD27: =AD18*$Q$7 -> 13950 | AE27: =AE18*$Q$7 -> 18000 | AF27: =AF18*$Q$7 -> 23250 | AG27: =AG18*$Q$7 -> 31500 | AH27: =AH18*$Q$7 -> 139500 | ... AJ27: =AJ18*$Q$7 -> 135000
O28: Mês 0 | P28: Mês 1 | Q28: Mês 2 | R28: Mês 3 | S28: Mês 4 | T28: Mês 5 | U28: Mês 6 | V28: Mês 7 | W28: Mês 8 | Z28: TOTAL | AA28: =AA25+AA26+AA27 -> 21000 | AB28: =AB25+AB26+AB27 -> 37200 | AC28: =AC25+AC26+AC27 -> 33600 | AD28: =AD25+AD26+AD27 -> 46500 | AE28: =AE25+AE26+AE27 -> 60000 | AF28: =AF25+AF26+AF27 -> 77500 | AG28: =AG25+AG26+AG27 -> 105000 | AH28: =AH25+AH26+AH27 -> 237150 | ... AK28: =AK25+AK26+AK27 -> 325500
O29: inicial | P29: Jan | Q29: Fev | R29: Mar | S29: Abr | T29: Mai | U29: Jun | V29: Jul | W29: Ago
N30: Lote 1 | O30: =O22/30 -> 7 | P30: =P22/30 -> 7.93 | Q30: =Q22/30 -> 8.77 | R30: =R22/30 -> 9.7 | S30: =S22/30 -> 10.5 | T30: =T22/30 -> 11.223333 | U30: =U22/30 -> 11.923333 | V30: =V22/30 -> 12.646667 | W30: =W22/30 -> 13.37
N31: Lote 2 | O31: =O23/30 -> 8 | P31: =P23/30 -> 8.93 | Q31: =Q23/30 -> 9.77 | R31: =R23/30 -> 10.7 | S31: =S23/30 -> 11.5 | T31: =T23/30 -> 12.223333 | U31: =U23/30 -> 12.923333 | V31: =V23/30 -> 13.646667 | W31: =W23/30 -> 14.37
N32: Lote 3 | O32: =O24/30 -> 9 | P32: =P24/30 -> 9.93 | Q32: =Q24/30 -> 10.77 | R32: =R24/30 -> 11.7 | S32: =S24/30 -> 12.5 | T32: =T24/30 -> 13.223333 | U32: =U24/30 -> 13.923333 | V32: =V24/30 -> 14.646667
N35: CONFINAMENTO (KG)
N36: 1.5 | O36: Mês 0 | P36: Mês 1 | Q36: Mês 2 | R36: Mês 3 | S36: Mês 4
O37: Entrada | P37: jul | Q37: ago | R37: set | S37: out
P38: 31 | Q38: 31 | R38: 30 | S38: 31
N39: Lote 3 | O39: =V24 -> 439.4 | P39: =(P38*$N$36)+O39 -> 485.9 | Q39: =(Q38*$N$36)+P39 -> 532.4 | R39: =(13*$N$36)+Q39 -> 551.9
N40: Lote 2 | O40: =W23 -> 431.1 | Q40: =(Q38*$N$36)+O40 -> 477.6 | R40: =(R38*$N$36)+Q40 -> 522.6 | S40: =(19*$N$36)+R40 -> 551.1
N41: Lote 1 | O41: =W22 -> 401.1 | Q41: =(Q38*$N$36)+O41 -> 447.6 | R41: =(R38*$N$36)+Q41 -> 492.6 | S41: =(S38*$N$36)+R41 -> 539.1
N44: CONFINAMENTO (@)
N45: 1.5 | O45: Mês 0 | P45: Mês 1 | Q45: Mês 2 | R45: Mês 3 | S45: Mês 4
...

Sheet PE LOTE 2
H4: MÊS 1 | I4: MÊS 2 | J4: MÊS 3 | K4: MÊS 4 | L4: MÊS 5 | M4: MÊS 6 | N4: MÊS 7 | O4: MÊS 8 | P4: MÊS 9 | Q4: MÊS 10 | R4: MÊS 11
H5: 45992 | I5: 46023 | J5: 46054 | K5: 46082 | L5: 46113 | M5: 46143 | N5: 46174 | O5: 46204 | P5: 46235 | Q5: 46266 | R5: 46296
G6: Quantidade | H6: =Produção!$Q$6 -> 500 | I6: =Produção!$Q$6 -> 500 | J6: =Produção!$Q$6 -> 500 | K6: =Produção!$Q$6 -> 500 | L6: =Produção!$Q$6 -> 500 | M6: =Produção!$Q$6 -> 500 | N6: =Produção!$Q$6 -> 500 | O6: =Produção!$Q$6 -> 500 | ... R6: =Produção!$Q$6 -> 500
G8: Entrada | H8: 46001 | I8: =H9+1 -> 46023 | J8: =I9+1 -> 46054 | K8: =J9+1 -> 46082 | L8: =K9+1 -> 46113 | M8: =L9+1 -> 46143 | N8: =M9+1 -> 46174 | O8: =N9+1 -> 46204 | P8: =O9+1 -> 46235 | ... R8: =Q9+1 -> 46296
G9: Saída | H9: 46022 | I9: 46053 | J9: 46081 | K9: 46112 | L9: 46142 | M9: 46173 | N9: 46203 | O9: 46234 | P9: 46265 | Q9: 46295 | R9: 46326
G10: Peso de Entrada @ | H10: =H11/30 -> 8 | I10: =I11/30 -> 8.63 | J10: =J11/30 -> 9.56 | K10: =K11/30 -> 10.4 | L10: =L11/30 -> 11.226667
G11: Peso de Entrada Kg | H11: =Produção!R6 -> 240 | I11: =H12 -> 258.9 | J11: =I12 -> 286.8 | K11: =J12 -> 312 | L11: =K12 -> 336.8 | M11: =L12 -> 357.8 | N11: =M12 -> 379.5 | O11: =N12 -> 400.5 | P11: =O12 -> 422.2 | ... R11: =Q12 -> 513.7
G12: Peso de Saída (kg) | H12: =H11+H16 -> 258.9 | I12: =I11+I16 -> 286.8 | J12: =J11+J16 -> 312 | K12: =K11+K16 -> 336.8 | L12: =L11+L16 -> 357.8 | M12: =M11+M16 -> 379.5 | N12: =N11+N16 -> 400.5 | O12: =O11+O16 -> 422.2 | ... R12: =R11+R16 -> 560.2
G13: Período (dias) | H13: =H9-H8 -> 21 | I13: =(I9-I8)+1 -> 31 | J13: =(J9-J8)+1 -> 28 | K13: =(K9-K8)+1 -> 31 | L13: =(L9-L8)+1 -> 30 | M13: =(M9-M8)+1 -> 31 | N13: =(N9-N8)+1 -> 30 | O13: =(O9-O8)+1 -> 31 | P13: =(P9-P8)+1 -> 31 | ... R13: =(R9-R8)+1 -> 31
G14: Custo da Diária | H14: =Produção!AA8+((Fluxo!K14/30)/(Produção!$Q$5+Produção!$Q$6+Produção!$Q$7)) -> 3.0066667 | I14: =Produção!AB8+((Fluxo!L14/30)/(Produção!$Q$5+Produção!$Q$6+Produção!$Q$7)) -> 3.2066667 | J14: =Produção!AC8+((Fluxo!M14/30)/(Produção!$Q$5+Produção!$Q$6+Produção!$Q$7)) -> 3.2066667 | K14: =Produção!AD8+((Fluxo!N14/30)/(Produção!$Q$5+Produção!$Q$6+Produção!$Q$7)) -> 3.5066667 | L14: =Produção!AE8+((Fluxo!O14/30)/(Produção!$Q$5+Produção!$Q$6+Produção!$Q$7)) -> 4.0066667 | M14: =Produção!AF8+((Fluxo!P14/30)/(Produção!$Q$5+Produção!$Q$6+Produção!$Q$7)) -> 4.5066667 | N14: =Produção!AG8+((Fluxo!Q14/30)/(Produção!$Q$5+Produção!$Q$6+Produção!$Q$7)) -> 5.5066667 | O14: =Produção!AH8+((Fluxo!R14/30)/(Produção!$Q$5+Produção!$Q$6+Produção!$Q$7)) -> 6.5066667 | P14: =Produção!AI8+((Fluxo!R14/30)/(Produção!$Q$5+Produção!$Q$6+Produção!$Q$7)) -> 17.006667 | Q14: =Produção!AJ8+((Fluxo!S14/30)/(Produção!$Q$5+Produção!$Q$6+Produção!$Q$7)) -> 17.006667 | R14: =Produção!AK8+((Fluxo!T14/30)/(Produção!$Q$5+Produção!$Q$6+Produção!$Q$7)) -> 17.006667
G15: Ganho de Peso Dia (Kg) | H15: =Produção!O13 -> 0.9 | I15: =Produção!P13 -> 0.9 | J15: =Produção!Q13 -> 0.9 | K15: =Produção!R13 -> 0.8 | L15: =Produção!S13 -> 0.7 | M15: =Produção!T13 -> 0.7 | N15: =Produção!U13 -> 0.7 | O15: =Produção!V13 -> 0.7 | P15: 1.5 | Q15: 1.5 | R15: 1.5
G16: Ganho de Peso Animal (Kg) | H16: =H15*H13 -> 18.9 | I16: =I15*I13 -> 27.9 | J16: =J15*J13 -> 25.2 | K16: =K15*K13 -> 24.8 | L16: =L15*L13 -> 21 | M16: =M15*M13 -> 21.7 | N16: =N15*N13 -> 21 | O16: =O15*O13 -> 21.7 | ... R16: =R15*R13 -> 46.5
G17: Custo por @ | H17: =(H19+(H14*H13))/H22 -> 378.11587 | I17: =(I19+(I14*I13))/I22 -> 351.73082 | J17: =(J19+(J14*J13))/J22 -> 331.95513 | K17: =(K19+(K14*K13))/K22 -> 317.19477 | L17: =(L19+(L14*L13))/L22 -> 308.65623 | M17: =(M19+(M14*M13))/M22 -> 302.05112 | N17: =(N19+(N14*N13))/N22 -> 298.58777 | O17: =(O19+(O14*O13))/O22 -> 297.57366 | ... R17: =(R19+(R14*R13))/R22 -> 280.05258
G18: Custo por Lote | H18: =(H14*H6)*H13 -> 31570 | I18: =(I14*I6)*I13 -> 49703.333 | J18: =(J14*J6)*J13 -> 44893.333 | K18: =(K14*K6)*K13 -> 54353.333 | L18: =(L14*L6)*L13 -> 60100 | M18: =(M14*M6)*M13 -> 69853.333 | N18: =(N14*N6)*N13 -> 82600 | O18: =(O14*O6)*O13 -> 100853.33 | ... R18: =(R14*R6)*R13 -> 263603.33
G19: Valor do Animal | H19: =Produção!T6 -> 3200 | I19: =H28/I6 -> 3263.14 | J19: =I28/J6 -> 3362.5467 | K19: =J28/K6 -> 3452.3333 | L19: =K28/L6 -> 3561.04 | M19: =L28/M6 -> 3681.24 | N19: =M28/N6 -> 3820.9467 | O19: =N28/O6 -> 3986.1467 | P19: =O28/P6 -> 4187.8533 | ... R19: =Q28/R6 -> 5225.26
G20: Rendimento | H20: 0.5 | I20: 0.5 | J20: 0.5 | K20: 0.5 | L20: 0.5 | M20: 0.5 | N20: 0.5 | O20: 0.5 | P20: 0.5 | Q20: 0.5 | R20: 0.55
G21: Ganho de Peso @ | H21: =(H16*H20)/15 -> 0.63 | I21: =(I16*I20)/15 -> 0.93 | J21: =(J16*J20)/15 -> 0.84 | K21: =(K16*K20)/15 -> 0.82666667 | L21: =(L16*L20)/15 -> 0.7 | M21: =(M16*M20)/15 -> 0.72333333 | N21: =(N16*N20)/15 -> 0.7 | O21: =(O16*O20)/15 -> 0.72333333 | ... R21: =(R16*R20)/15 -> 1.705
G22: Total de @ Animal | H22: =(H12*H20)/15 -> 8.63 | I22: =(I12*I20)/15 -> 9.56 | J22: =(J12*J20)/15 -> 10.4 | K22: =(K12*K20)/15 -> 11.226667 | L22: =(L12*L20)/15 -> 11.926667 | M22: =(M12*M20)/15 -> 12.65 | N22: =(N12*N20)/15 -> 13.35 | O22: =(O12*O20)/15 -> 14.073333 | ... R22: =(R12*R20)/15 -> 20.540667
G23: Mortalidade | H23: 0 | I23: 0 | J23: 0 | K23: 0 | L23: 0 | M23: 0 | N23: 0 | O23: 0 | P23: 0 | Q23: 0 | R23: 0
G24: Total de @ | H24: =(H6-(H6*H23))*H22 -> 4315 | I24: =(I6-(I6*I23))*I22 -> 4780 | J24: =(J6-(J6*J23))*J22 -> 5200 | K24: =(K6-(K6*K23))*K22 -> 5613.3333 | L24: =(L6-(L6*L23))*L22 -> 5963.3333 | M24: =(M6-(M6*M23))*M22 -> 6325 | N24: =(N6-(N6*N23))*N22 -> 6675 | O24: =(O6-(O6*O23))*O22 -> 7036.6667 | ... R24: =(R6-(R6*R23))*R22 -> 10270.333
G25: Invest Animais | H25: =H6*H19 -> 1600000 | I25: =I6*I19 -> 1631570 | J25: =J6*J19 -> 1681273.3 | K25: =K6*K19 -> 1726166.7 | L25: =L6*L19 -> 1780520 | M25: =M6*M19 -> 1840620 | N25: =N6*N19 -> 1910473.3 | O25: =O6*O19 -> 1993073.3 | ... R25: =R6*R19 -> 2612630
G26: Invest Alimentação | H26: =H6*H13*H14 -> 31570 | I26: =I6*I13*I14 -> 49703.333 | J26: =J6*J13*J14 -> 44893.333 | K26: =K6*K13*K14 -> 54353.333 | L26: =L6*L13*L14 -> 60100 | M26: =M6*M13*M14 -> 69853.333 | N26: =N6*N13*N14 -> 82600 | O26: =O6*O13*O14 -> 100853.33 | ... R26: =R6*R13*R14 -> 263603.33
G27: Custo de Capital-CDI
G28: Investimento Total | H28: =H25+H26+H27 -> 1631570 | I28: =I25+I26+I27 -> 1681273.3 | J28: =J25+J26+J27 -> 1726166.7 | K28: =K25+K26+K27 -> 1780520 | L28: =L25+L26+L27 -> 1840620 | M28: =M25+M26+M27 -> 1910473.3 | N28: =N25+N26+N27 -> 1993073.3 | O28: =O25+O26+O27 -> 2093926.7 | ... R28: =R25+R26+R27 -> 2876233.3
G29: Ponto de Equilíbrio @ | H29: =(H28/H24) -> 378.11587 | I29: =I28/I24 -> 351.73082 | J29: =J28/J24 -> 331.95513 | K29: =K28/K24 -> 317.19477 | L29: =L28/L24 -> 308.65623 | M29: =M28/M24 -> 302.05112 | N29: =N28/N24 -> 298.58777 | O29: =O28/O24 -> 297.57366 | P29: =P28/P24 -> 301.79603 | ... R29: =R28/R24 -> 280.05258
G30: Peso do Animal | H30: =H25/H28 -> 0.98065054 | I30: =I25/I28 -> 0.97043709 | J30: =J25/J28 -> 0.97399247 | K30: =K25/K28 -> 0.96947334 | L30: =L25/L28 -> 0.96734796 | M30: =M25/M28 -> 0.96343664 | N30: =N25/N28 -> 0.95855647 | O30: =O25/O28 -> 0.95183531 | ... R30: =R25/R28 -> 0.9083512
G31: Peso da Produção | H31: =H26/H28 -> 0.019349461 | I31: =I26/I28 -> 0.029562911 | J31: =J26/J28 -> 0.026007531 | K31: =K26/K28 -> 0.030526663 | L31: =L26/L28 -> 0.032652041 | M31: =M26/M28 -> 0.036563365 | N31: =N26/N28 -> 0.041443533 | O31: =O26/O28 -> 0.048164692 | ... R31: =R26/R28 -> 0.0916488
G32: Peso do Custo de Capital | H32: =H27/H28 -> 0 | I32: =I27/I28 -> 0 | J32: =J27/J28 -> 0 | K32: =K27/K28 -> 0 | L32: =L27/L28 -> 0 | M32: =M27/M28 -> 0 | N32: =N27/N28 -> 0 | O32: =O27/O28 -> 0 | ... R32: =R27/R28 -> 0
G33: Cotação B3 | R33: 350
G34: Base da sua Região | R34: 0
G35: Cotação B3 - Base | H35: =H33-(H33*H34) -> 0 | I35: =I33-(I33*I34) -> 0 | J35: =J33-(J33*J34) -> 0 | K35: =K33-(K33*K34) -> 0 | L35: =L33-(L33*L34) -> 0 | M35: =M33-(M33*M34) -> 0 | N35: =N33-(N33*N34) -> 0 | O35: =O33-(O33*O34) -> 0 | ... R35: =R33-(R33*R34) -> 350
G36: Resultado p/ @ | H36: =H35-H29 -> -378.11587 | I36: =I35-I29 -> -351.73082 | J36: =J35-J29 -> -331.95513 | K36: =K35-K29 -> -317.19477 | L36: =L35-L29 -> -308.65623 | M36: =M35-M29 -> -302.05112 | N36: =N35-N29 -> -298.58777 | O36: =O35-O29 -> -297.57366 | ... R36: =R35-R29 -> 69.947421
G37: Faturamento | H37: =(H24*H35) -> 0 | I37: =(I24*I35) -> 0 | J37: =(J24*J35) -> 0 | K37: =(K24*K35) -> 0 | L37: =(L24*L35) -> 0 | M37: =(M24*M35) -> 0 | N37: =(N24*N35) -> 0 | O37: =(O24*O35) -> 0 | ... R37: =(R24*R35) -> 3594616.7
G38: Lucro Líquido na Operação | H38: =H37-H28 -> -1631570 | I38: =I37-I28 -> -1681273.3 | J38: =J37-J28 -> -1726166.7 | K38: =K37-K28 -> -1780520 | L38: =L37-L28 -> -1840620 | M38: =M37-M28 -> -1910473.3 | N38: =N37-N28 -> -1993073.3 | O38: =O37-O28 -> -2093926.7 | ... R38: =R37-R28 -> 718383.33
G39: Lucro Líquido por Animal | H39: =H38/(H6-(H6*H23)) -> -3263.14 | I39: =I38/(I6-(I6*I23)) -> -3362.5467 | J39: =J38/(J6-(J6*J23)) -> -3452.3333 | K39: =K38/(K6-(K6*K23)) -> -3561.04 | L39: =L38/(L6-(L6*L23)) -> -3681.24 | M39: =M38/(M6-(M6*M23)) -> -3820.9467 | N39: =N38/(N6-(N6*N23)) -> -3986.1467 | O39: =O38/(O6-(O6*O23)) -> -4187.8533 | ... R39: =R38/(R6-(R6*R23)) -> 1436.7667
G40: Taxa Líquida no Período | H40: =H38/H28 -> -1 | I40: =I38/I28 -> -1 | J40: =J38/J28 -> -1 | K40: =K38/K28 -> -1 | L40: =L38/L28 -> -1 | M40: =M38/M28 -> -1 | N40: =N38/N28 -> -1 | O40: =O38/O28 -> -1 | ... R40: =R38/R28 -> 0.24976532
G41: Taxa Líquida ao Mês | H41: =((1+H40)^(1/(H13/30)))-1 -> -1 | I41: =((1+I40)^(1/(I13/30)))-1 -> -1 | J41: =((1+J40)^(1/(J13/30)))-1 -> -1 | K41: =((1+K40)^(1/(K13/30)))-1 -> -1 | L41: =((1+L40)^(1/(L13/30)))-1 -> -1 | M41: =((1+M40)^(1/(M13/30)))-1 -> -1 | N41: =((1+N40)^(1/(N13/30)))-1 -> -1 | O41: =((1+O40)^(1/(O13/30)))-1 -> -1 | ... R41: =((1+R40)^(1/(R13/30)))-1 -> 0.2408091
G42: Taxa Líquida ao Ano | H42: =((1+H41)^12)-1 -> -1 | I42: =((1+I41)^12)-1 -> -1 | J42: =((1+J41)^12)-1 -> -1 | K42: =((1+K41)^12)-1 -> -1 | L42: =((1+L41)^12)-1 -> -1 | M42: =((1+M41)^12)-1 -> -1 | N42: =((1+N41)^12)-1 -> -1 | O42: =((1+O41)^12)-1 -> -1 | ... R42: =((1+R41)^12)-1 -> 12.318632

Sheet PE LOTE 3
H4: MÊS 1 | I4: MÊS 2 | J4: MÊS 3 | K4: MÊS 4 | L4: MÊS 5 | M4: MÊS 6 | N4: MÊS 7 | O4: MÊS 8 | P4: MÊS 9 | Q4: MÊS 10
H5: 45992 | I5: 46023 | J5: 46054 | K5: 46082 | L5: 46113 | M5: 46143 | N5: 46174 | O5: 46204 | P5: 46235 | Q5: 46266
G6: Quantidade | H6: =Produção!$Q$7 -> 300 | I6: =Produção!$Q$7 -> 300 | J6: =Produção!$Q$7 -> 300 | K6: =Produção!$Q$7 -> 300 | L6: =Produção!$Q$7 -> 300 | M6: =Produção!$Q$7 -> 300 | N6: =Produção!$Q$7 -> 300 | O6: =Produção!$Q$7 -> 300 | ... Q6: =Produção!$Q$7 -> 300
G8: Entrada | H8: 46001 | I8: =H9+1 -> 46023 | J8: =I9+1 -> 46054 | K8: =J9+1 -> 46082 | L8: =K9+1 -> 46113 | M8: =L9+1 -> 46143 | N8: =M9+1 -> 46174 | O8: =N9+1 -> 46204 | P8: =O9+1 -> 46235 | Q8: =P9+1 -> 46266
G9: Saída | H9: 46022 | I9: 46053 | J9: 46081 | K9: 46112 | L9: 46142 | M9: 46173 | N9: 46203 | O9: 46234 | P9: 46265 | Q9: 46295
G10: Peso de Entrada @ | H10: =H11/30 -> 9 | I10: =I11/30 -> 9.63 | J10: =J11/30 -> 10.56 | K10: =K11/30 -> 11.4 | L10: =L11/30 -> 12.226667
G11: Peso de Entrada Kg | H11: =Produção!R7 -> 270 | I11: =H12 -> 288.9 | J11: =I12 -> 316.8 | K11: =J12 -> 342 | L11: =K12 -> 366.8 | M11: =L12 -> 387.8 | N11: =M12 -> 409.5 | O11: =N12 -> 430.5 | P11: =O12 -> 452.2 | Q11: =P12 -> 498.7
G12: Peso de Saída (kg) | H12: =H11+H16 -> 288.9 | I12: =I11+I16 -> 316.8 | J12: =J11+J16 -> 342 | K12: =K11+K16 -> 366.8 | L12: =L11+L16 -> 387.8 | M12: =M11+M16 -> 409.5 | N12: =N11+N16 -> 430.5 | O12: =O11+O16 -> 452.2 | ... Q12: =Q11+Q16 -> 543.7
G13: Período (dias) | H13: =H9-H8 -> 21 | I13: =(I9-I8)+1 -> 31 | J13: =(J9-J8)+1 -> 28 | K13: =(K9-K8)+1 -> 31 | L13: =(L9-L8)+1 -> 30 | M13: =(M9-M8)+1 -> 31 | N13: =(N9-N8)+1 -> 30 | O13: =(O9-O8)+1 -> 31 | P13: =(P9-P8)+1 -> 31 | Q13: =(Q9-Q8)+1 -> 30
G14: Custo da Diária | H14: =Produção!AA9+((Fluxo!K14/30)/(Produção!$Q$5+Produção!$Q$6+Produção!$Q$7)) -> 3.0066667 | I14: =Produção!AB9+((Fluxo!L14/30)/(Produção!$Q$5+Produção!$Q$6+Produção!$Q$7)) -> 3.2066667 | J14: =Produção!AC9+((Fluxo!M14/30)/(Produção!$Q$5+Produção!$Q$6+Produção!$Q$7)) -> 3.2066667 | K14: =Produção!AD9+((Fluxo!N14/30)/(Produção!$Q$5+Produção!$Q$6+Produção!$Q$7)) -> 3.5066667 | L14: =Produção!AE9+((Fluxo!O14/30)/(Produção!$Q$5+Produção!$Q$6+Produção!$Q$7)) -> 4.0066667 | M14: =Produção!AF9+((Fluxo!P14/30)/(Produção!$Q$5+Produção!$Q$6+Produção!$Q$7)) -> 4.5066667 | N14: =Produção!AG9+((Fluxo!Q14/30)/(Produção!$Q$5+Produção!$Q$6+Produção!$Q$7)) -> 5.5066667 | O14: =Produção!AH9+((Fluxo!R14/30)/(Produção!$Q$5+Produção!$Q$6+Produção!$Q$7)) -> 17.006667 | ... Q14: =Produção!AJ9+((Fluxo!T14/30)/(Produção!$Q$5+Produção!$Q$6+Produção!$Q$7)) -> 17.006667
G15: Ganho de Peso Dia (Kg) | H15: =Produção!O13 -> 0.9 | I15: =Produção!P13 -> 0.9 | J15: =Produção!Q13 -> 0.9 | K15: =Produção!R13 -> 0.8 | L15: =Produção!S13 -> 0.7 | M15: =Produção!T13 -> 0.7 | N15: =Produção!U13 -> 0.7 | O15: =Produção!V13 -> 0.7 | P15: 1.5 | Q15: 1.5
G16: Ganho de Peso Animal (Kg) | H16: =H15*H13 -> 18.9 | I16: =I15*I13 -> 27.9 | J16: =J15*J13 -> 25.2 | K16: =K15*K13 -> 24.8 | L16: =L15*L13 -> 21 | M16: =M15*M13 -> 21.7 | N16: =N15*N13 -> 21 | O16: =O15*O13 -> 21.7 | ... Q16: =Q15*Q13 -> 45
G17: Custo por @ | H17: =(H19+(H14*H13))/H22 -> 371.04258 | I17: =(I19+(I14*I13))/I22 -> 347.77904 | J17: =(J19+(J14*J13))/J22 -> 330.02924 | K17: =(K19+(K14*K13))/K22 -> 316.60632 | L17: =(L19+(L14*L13))/L22 -> 308.76019 | M17: =(M19+(M14*M13))/M22 -> 302.63346 | N17: =(N19+(N14*N13))/N22 -> 299.38304 | O17: =(O19+(O14*O13))/O22 -> 319.99248 | ... Q17: =(Q19+(Q14*Q13))/Q22 -> 293.98365
G18: Custo por Lote | H18: =(H14*H6)*H13 -> 18942 | I18: =(I14*I6)*I13 -> 29822 | J18: =(J14*J6)*J13 -> 26936 | K18: =(K14*K6)*K13 -> 32612 | L18: =(L14*L6)*L13 -> 36060 | M18: =(M14*M6)*M13 -> 41912 | N18: =(N14*N6)*N13 -> 49560 | O18: =(O14*O6)*O13 -> 158162 | ... Q18: =(Q14*Q6)*Q13 -> 153060
G19: Valor do Animal | H19: =Produção!T7 -> 3510 | I19: =H28/I6 -> 3573.14 | J19: =I28/J6 -> 3672.5467 | K19: =J28/K6 -> 3762.3333 | L19: =K28/L6 -> 3871.04 | M19: =L28/M6 -> 3991.24 | N19: =M28/N6 -> 4130.9467 | O19: =N28/O6 -> 4296.1467 | P19: =O28/P6 -> 4823.3533 | Q19: =P28/Q6 -> 5350.56
G20: Rendimento | H20: 0.5 | I20: 0.5 | J20: 0.5 | K20: 0.5 | L20: 0.5 | M20: 0.5 | N20: 0.5 | O20: 0.5 | P20: 0.5 | Q20: 0.55
G21: Ganho de Peso @ | H21: =(H16*H20)/15 -> 0.63 | I21: =(I16*I20)/15 -> 0.93 | J21: =(J16*J20)/15 -> 0.84 | K21: =(K16*K20)/15 -> 0.82666667 | L21: =(L16*L20)/15 -> 0.7 | M21: =(M16*M20)/15 -> 0.72333333 | N21: =(N16*N20)/15 -> 0.7 | O21: =(O16*O20)/15 -> 0.72333333 | ... Q21: =(Q16*Q20)/15 -> 1.65
G22: Total de @ Animal | H22: =(H12*H20)/15 -> 9.63 | I22: =(I12*I20)/15 -> 10.56 | J22: =(J12*J20)/15 -> 11.4 | K22: =(K12*K20)/15 -> 12.226667 | L22: =(L12*L20)/15 -> 12.926667 | M22: =(M12*M20)/15 -> 13.65 | N22: =(N12*N20)/15 -> 14.35 | O22: =(O12*O20)/15 -> 15.073333 | ... Q22: =(Q12*Q20)/15 -> 19.935667
G23: Mortalidade | H23: 0 | I23: 0 | J23: 0 | K23: 0 | L23: 0 | M23: 0 | N23: 0 | O23: 0 | P23: 0 | Q23: 0
G24: Total de @ | H24: =(H6-(H6*H23))*H22 -> 2889 | I24: =(I6-(I6*I23))*I22 -> 3168 | J24: =(J6-(J6*J23))*J22 -> 3420 | K24: =(K6-(K6*K23))*K22 -> 3668 | L24: =(L6-(L6*L23))*L22 -> 3878 | M24: =(M6-(M6*M23))*M22 -> 4095 | N24: =(N6-(N6*N23))*N22 -> 4305 | O24: =(O6-(O6*O23))*O22 -> 4522 | ... Q24: =(Q6-(Q6*Q23))*Q22 -> 5980.7
G25: Invest Animais | H25: =H6*H19 -> 1053000 | I25: =I6*I19 -> 1071942 | J25: =J6*J19 -> 1101764 | K25: =K6*K19 -> 1128700 | L25: =L6*L19 -> 1161312 | M25: =M6*M19 -> 1197372 | N25: =N6*N19 -> 1239284 | O25: =O6*O19 -> 1288844 | ... Q25: =Q6*Q19 -> 1605168
G26: Invest Alimentação | H26: =H6*H13*H14 -> 18942 | I26: =I6*I13*I14 -> 29822 | J26: =J6*J13*J14 -> 26936 | K26: =K6*K13*K14 -> 32612 | L26: =L6*L13*L14 -> 36060 | M26: =M6*M13*M14 -> 41912 | N26: =N6*N13*N14 -> 49560 | O26: =O6*O13*O14 -> 158162 | ... Q26: =Q6*Q13*Q14 -> 153060
G27: Custo de Capital-CDI | M27: =((M25*(1+$F$24)^M13)-M25)+((M26*((1+$F$24)^30)-M26)) -> 0 | N27: =((N25*(1+$F$24)^N13)-N25)+((N26*((1+$F$24)^120)-N26)) -> 0 | O27: =((O25*(1+$F$24)^O13)-O25)+((O26*((1+$F$24)^120)-O26)) -> 0 | P27: =((P25*(1+$F$24)^P13)-P25)+((P26*((1+$F$24)^120)-P26)) -> 0 | Q27: =((Q25*(1+$F$24)^Q13)-Q25)+((Q26*((1+$F$24)^120)-Q26)) -> 0
G28: Investimento Total | H28: =H25+H26+H27 -> 1071942 | I28: =I25+I26+I27 -> 1101764 | J28: =J25+J26+J27 -> 1128700 | K28: =K25+K26+K27 -> 1161312 | L28: =L25+L26+L27 -> 1197372 | M28: =M25+M26+M27 -> 1239284 | N28: =N25+N26+N27 -> 1288844 | O28: =O25+O26+O27 -> 1447006 | ... Q28: =Q25+Q26+Q27 -> 1758228
G29: Ponto de Equilíbrio @ | H29: =(H28/H24) -> 371.04258 | I29: =I28/I24 -> 347.77904 | J29: =J28/J24 -> 330.02924 | K29: =K28/K24 -> 316.60632 | L29: =L28/L24 -> 308.76019 | M29: =M28/M24 -> 302.63346 | N29: =N28/N24 -> 299.38304 | O29: =O28/O24 -> 319.99248 | P29: =P28/P24 -> 321.87046 | Q29: =Q28/Q24 -> 293.98365
G30: Peso do Animal | H30: =H25/H28 -> 0.98232927 | I30: =I25/I28 -> 0.9729325 | J30: =J25/J28 -> 0.97613538 | K30: =K25/K28 -> 0.97191797 | L30: =L25/L28 -> 0.96988405 | M30: =M25/M28 -> 0.96618047 | N30: =N25/N28 -> 0.96154694 | O30: =O25/O28 -> 0.89069707 | ... Q30: =Q25/Q28 -> 0.91294644
G31: Peso da Produção | H31: =H26/H28 -> 0.017670732 | I31: =I26/I28 -> 0.027067503 | J31: =J26/J28 -> 0.023864623 | K31: =K26/K28 -> 0.028082031 | L31: =L26/L28 -> 0.030115954 | M31: =M26/M28 -> 0.033819528 | N31: =N26/N28 -> 0.038453063 | O31: =O26/O28 -> 0.10930293 | ... Q31: =Q26/Q28 -> 0.087053556
G32: Peso do Custo de Capital | H32: =H27/H28 -> 0 | I32: =I27/I28 -> 0 | J32: =J27/J28 -> 0 | K32: =K27/K28 -> 0 | L32: =L27/L28 -> 0 | M32: =M27/M28 -> 0 | N32: =N27/N28 -> 0 | O32: =O27/O28 -> 0 | ... Q32: =Q27/Q28 -> 0
G33: Cotação B3
G34: Base da sua Região
G35: Cotação B3 - Base | H35: =H33-(H33*H34) -> 0 | I35: =I33-(I33*I34) -> 0 | J35: =J33-(J33*J34) -> 0 | K35: =K33-(K33*K34) -> 0 | L35: =L33-(L33*L34) -> 0 | M35: =M33-(M33*M34) -> 0 | N35: =N33-(N33*N34) -> 0 | O35: =O33-(O33*O34) -> 0 | ... Q35: =Q33-(Q33*Q34) -> 0
G36: Resultado p/ @ | H36: =H35-H29 -> -371.04258 | I36: =I35-I29 -> -347.77904 | J36: =J35-J29 -> -330.02924 | K36: =K35-K29 -> -316.60632 | L36: =L35-L29 -> -308.76019 | M36: =M35-M29 -> -302.63346 | N36: =N35-N29 -> -299.38304 | O36: =O35-O29 -> -319.99248 | ... Q36: =Q35-Q29 -> -293.98365
G37: Faturamento | H37: =(H24*H35) -> 0 | I37: =(I24*I35) -> 0 | J37: =(J24*J35) -> 0 | K37: =(K24*K35) -> 0 | L37: =(L24*L35) -> 0 | M37: =(M24*M35) -> 0 | N37: =(N24*N35) -> 0 | O37: =(O24*O35) -> 0 | ... Q37: =(Q24*Q35) -> 0
G38: Lucro Líquido na Operação | H38: =H37-H28 -> -1071942 | I38: =I37-I28 -> -1101764 | J38: =J37-J28 -> -1128700 | K38: =K37-K28 -> -1161312 | L38: =L37-L28 -> -1197372 | M38: =M37-M28 -> -1239284 | N38: =N37-N28 -> -1288844 | O38: =O37-O28 -> -1447006 | ... Q38: =Q37-Q28 -> -1758228
G39: Lucro Líquido por Animal | H39: =H38/(H6-(H6*H23)) -> -3573.14 | I39: =I38/(I6-(I6*I23)) -> -3672.5467 | J39: =J38/(J6-(J6*J23)) -> -3762.3333 | K39: =K38/(K6-(K6*K23)) -> -3871.04 | L39: =L38/(L6-(L6*L23)) -> -3991.24 | M39: =M38/(M6-(M6*M23)) -> -4130.9467 | N39: =N38/(N6-(N6*N23)) -> -4296.1467 | O39: =O38/(O6-(O6*O23)) -> -4823.3533 | ... Q39: =Q38/(Q6-(Q6*Q23)) -> -5860.76
